Workbook

Sheet Table of Contents
A1: Dynamic Compression Experiment
A2: 1. Experiment List
A3: 2. Data Summary
A4: 3. Data Statistics
A5: 4. Viability
A6: 5. Biochem
A7: 5.1 - Alamar Blue Raw
A8: 5.2 - Alamar Blue Analysis
A9: 5.3 - PicoGreen
A10: 5.4 - DMMB
A11: 5.5 - OHP
A12: 5.6 - Weights
A13: 5.7 - Rx

Sheet Experiment List
A1: Experiment Name | B1: Date | C1: Group | D1: Output 1 | E1: Output 2 | J1: Sample Size
A2: DC1 | B2: 8/15-8/22 | C2: 4m 5% | D2: N/A | E2: N/A | J2: Age | K2: Strain | L2: Time | M2: Viability | N2: Biochem | O2: Dual Rx | P2: Thymidine | Q2: Histology | R2: PCR
A3: DC2 | B3: 8/25-9/1 | C3: 24m 5% | D3: Rx - 1? | E3: N/A | J3: 4m | K3: 0.05 | L3: D1
A4: DC3 | B4: 9/5-9/12 | C4: 4m 5% | D4: Rx - 5 | E4: N/A | L4: D7 | N4: 5 | O4: 5
A5: DC4 | B5: 9/19-9/26 | C5: 24m 5% | K5: 0.15 | L5: D1
L6: D7
J7: 24m | K7: 0.05 | L7: D1
L8: D7 | N8: 7 | O8: 7
K9: 0.15 | L9: D1
L10: D7 | N10: 4 | O10: 4

Sheet Data Summary
A1: Table of Contents | B1: Age | C1: Sex | D1: Strain | E1: Time | F1: % Live | G1: Alamar Blue | H1: Picogreen | J1: DMMB | M1: OHP - Collagen | P1: Proline Incorporation | S1: S35 Incorporation | V1: Thymidine Incorporation
H2: Raw | I2: Picogreen (DW) | J2: Raw | K2: DNA | L2: DW | M2: Raw (ug) | N2: DNA | O2: DW (ug/mg) | P2: Raw | Q2: DNA | R2: DW | S2: Raw | T2: DNA | U2: DW | V2: Raw | W2: DNA | X2: DW
B3: 4m | C3: Male | D3: 0.05 | E3: D1
E4: D7
D5: 0.15 | E5: D1
E6: D7
B7: 24m | C7: Male | D7: 0.05 | E7: D1
E8: D7
D9: 0.15 | E9: D1
E10: D7

Sheet Statistics
A1: Table of Contents
B2: Age + Sex | C2: Strain | D2: Timepoint | E2: % Live - By Sample | H2: % Live - By Image | K2: AB | N2: Picogreen (DW) | Q2: DMMB (DW) | T2: OHP(DW) | W2: Proline(DW) | Z2: S35(DW) | AC2: Thymidine(DW)
E3: Mean | F3: St Dev | G3: Count | H3: Mean | I3: St Dev | J3: Count | K3: Mean | L3: St Dev | M3: Count | N3: Mean | O3: St Dev | P3: Count | Q3: Mean | R3: St Dev | S3: Count | T3: Mean | U3: St Dev | V3: Count | W3: Mean | X3: St Dev | Y3: Count | Z3: Mean | AA3: St Dev | AB3: Count | AC3: Mean | AD3: St Dev | AE3: Count
B4: 4m-male | D4: D0 | E4: 39.009623 | F4: 10.472338 | G4: 4 | H4: 39.009623 | I4: 11.870245 | J4: 8 | K4: 1.2432736 | L4: 0.074529071 | M4: 8 | N4: 150.83507 | O4: 51.74052 | P4: 6 | Q4: 612.40795 | R4: 109.58385 | S4: 6 | T4: 174.59314 | U4: 36.666754 | V4: 6 | AF4: 2619.6667 | AG4: 383.67078 | AH4: 3 | AI4: 0.0038176667 | AJ4: 0.00079198253 | AK4: 3 | AL4: 0.26864552 | AM4: 0.052847587 | AN4: 3 | AO4: 1.8753856 | AP4: 0.023992398 | AQ4: 3 | AR4: 29.19928 | AS4: 7.2258772 | AT4: 3 | AU4: 0.93122222 | AV4: 0.013459129 | AW4: 3 | AX4: 86.662222 | AY4: 4.5343447 | AZ4: 3 | BA4: 0.98122222 | BB4: 0.0083688134 | BC4: 3
C5: 0.05 | D5: D1 | K5: =AVERAGE('Biochem Summary'!G11:G21) -> 1.3322142 | L5: =STDEV('Biochem Summary'!G11:G21) -> 0.17034275 | M5: 11 | N5: =AVERAGE('Biochem Summary'!I11:I21) -> 119.18294 | O5: =STDEV('Biochem Summary'!I11:I21) -> 20.251761 | P5: =COUNT('Biochem Summary'!I11:I21) -> 11 | Q5: =AVERAGE('Biochem Summary'!L11:L21) -> 513.88302 | R5: =STDEV('Biochem Summary'!L11:L21) -> 47.582311 | S5: =COUNT('Biochem Summary'!L11:L21) -> 11 | T5: =AVERAGE('Biochem Summary'!O11:O21) -> 205.84009 | U5: =STDEV('Biochem Summary'!O11:O21) -> 78.434477 | V5: 11 | W5: =AVERAGE('Biochem Summary'!R11:R21) -> 0.0015097443 | X5: =STDEV('Biochem Summary'!R11:R21) -> 0.0014919756 | Y5: 11 | Z5: =AVERAGE('Biochem Summary'!U11:U21) -> 1.8827039 | AA5: =STDEV('Biochem Summary'!U11:U21) -> 0.89630384 | AB5: 11
D6: D7 | K6: =AVERAGE('Biochem Summary'!G48:G57) -> 1.4418092 | L6: =STDEV('Biochem Summary'!G48:G57) -> 0.12759275 | M6: =COUNT('Biochem Summary'!G48:G57) -> 8 | N6: =AVERAGE('Biochem Summary'!I48:I57) -> 43.135964 | O6: =STDEV('Biochem Summary'!I48:I57) -> 14.621319 | P6: =COUNT('Biochem Summary'!K48:K57) -> 7 | Q6: =AVERAGE('Biochem Summary'!L48:L57) -> 422.79686 | R6: =STDEV('Biochem Summary'!L48:L57) -> 77.303035 | S6: =COUNT('Biochem Summary'!L48:L57) -> 7 | T6: =AVERAGE('Biochem Summary'!O48:O57) -> 192.92931 | U6: =STDEV('Biochem Summary'!O48:O57) -> 102.00892 | V6: 7 | W6: =AVERAGE('Biochem Summary'!R48:R57) -> 0.00079472197 | X6: =STDEV('Biochem Summary'!R48:R57) -> 0.00058257152 | Y6: =COUNT('Biochem Summary'!R48:R57) -> 7 | Z6: =AVERAGE('Biochem Summary'!U48:U57) -> 1.2736106 | AA6: =STDEV('Biochem Summary'!U48:U57) -> 0.52478632 | AB6: =COUNT('Biochem Summary'!U48:U57) -> 7
C7: 0.15 | D7: D1 | K7: =AVERAGE('Biochem Summary'!G22:G32) -> 1.4631902 | L7: =STDEV('Biochem Summary'!G22:G32) -> 0.17519608 | M7: =COUNT('Biochem Summary'!G22:G32) -> 6 | N7: =AVERAGE('Biochem Summary'!I22:I32) -> 102.55101 | O7: =STDEV('Biochem Summary'!I22:I32) -> 47.53408 | P7: =COUNT('Biochem Summary'!I22:I32) -> 10 | Q7: =AVERAGE('Biochem Summary'!L22:L32) -> 528.63646 | R7: =STDEV('Biochem Summary'!L22:L32) -> 108.28852 | S7: =COUNT('Biochem Summary'!L22:L32) -> 10 | T7: =AVERAGE('Biochem Summary'!O22:O32) -> 192.87068 | U7: =STDEV('Biochem Summary'!O22:O32) -> 27.249101 | V7: 10 | W7: =AVERAGE('Biochem Summary'!R22:R32) -> 0.0016995766 | X7: =STDEV('Biochem Summary'!R22:R32) -> 0.0013604158 | Y7: 10 | Z7: =AVERAGE('Biochem Summary'!U22:U32) -> 1.9413706 | AA7: =STDEV('Biochem Summary'!U22:U32) -> 0.82423013 | AB7: =COUNT('Biochem Summary'!U22:U32) -> 10
D8: D7 | K8: =AVERAGE('Biochem Summary'!G58:G77) -> 2.4449692 | L8: =STDEV('Biochem Summary'!G58:G77) -> 0.52846854 | M8: =COUNT('Biochem Summary'!G58:G77) -> 12 | N8: =AVERAGE('Biochem Summary'!I58:I77) -> 47.896515 | O8: =STDEV('Biochem Summary'!I58:I77) -> 14.40118 | P8: =COUNT('Biochem Summary'!I58:I77) -> 10 | Q8: =AVERAGE('Biochem Summary'!L58:L77) -> 396.41981 | R8: =STDEV('Biochem Summary'!L58:L77) -> 136.71096 | S8: =COUNT('Biochem Summary'!L58:L77) -> 14 | T8: =AVERAGE('Biochem Summary'!O58:O77) -> 175.56916 | U8: =STDEV('Biochem Summary'!O58:O77) -> 30.530226 | V8: 14 | W8: =AVERAGE('Biochem Summary'!R58:R77) -> 0.0015845715 | X8: =STDEV('Biochem Summary'!R58:R77) -> 0.002164495 | Y8: =COUNT('Biochem Summary'!R58:R77) -> 14 | Z8: =AVERAGE('Biochem Summary'!U58:U77) -> 2.8138329 | AA8: =STDEV('Biochem Summary'!U58:U77) -> 3.2173104 | AB8: =COUNT('Biochem Summary'!U58:U77) -> 14
C9: 0.3 | D9: D1 | K9: =AVERAGE('Biochem Summary'!G231:G235) -> 1.5134328 | L9: =STDEV('Biochem Summary'!G231:G235) -> 0.16606783 | M9: =COUNT('Biochem Summary'!G231:G235) -> 5 | N9: =AVERAGE('Biochem Summary'!I231:I235) -> 69.393489 | O9: =STDEV('Biochem Summary'!I231:I235) -> 24.902391 | P9: 5 | Q9: =AVERAGE('Biochem Summary'!L231:L235) -> 441.6438 | R9: =STDEV('Biochem Summary'!L231:L235) -> 14.725938 | S9: 5 | T9: =AVERAGE('Biochem Summary'!O231:O235) -> 218.29219 | U9: =STDEV('Biochem Summary'!O231:O235) -> 11.724579 | V9: 5 | W9: =AVERAGE('Biochem Summary'!R231:R235) -> 0.00074483855 | X9: =STDEV('Biochem Summary'!R231:R235) -> 0.00017496623 | Y9: 5 | Z9: =AVERAGE('Biochem Summary'!U231:U235) -> 2.4046623 | AA9: =STDEV('Biochem Summary'!U231:U235) -> 0.73178755 | AB9: 5
D10: D7 | K10: =AVERAGE('Biochem Summary'!G236:G240) -> 2.0730539 | L10: =STDEV('Biochem Summary'!G236:G240) -> 0.28524623 | M10: =COUNT('Biochem Summary'!G236:G240) -> 5 | N10: =AVERAGE('Biochem Summary'!I236:I240) -> 25.739559 | O10: =STDEV('Biochem Summary'!I236:I240) -> 15.575427 | P10: 5 | Q10: =AVERAGE('Biochem Summary'!L236:L240) -> 366.98137 | R10: =STDEV('Biochem Summary'!L236:L240) -> 33.774547 | S10: 5 | T10: =AVERAGE('Biochem Summary'!O236:O240) -> 220.82534 | U10: =STDEV('Biochem Summary'!O236:O240) -> 14.464402 | V10: 5 | W10: =AVERAGE('Biochem Summary'!R236:R240) -> 0.0013242268 | X10: =STDEV('Biochem Summary'!R236:R240) -> 0.00060772298 | Y10: 5 | Z10: =AVERAGE('Biochem Summary'!U236:U240) -> 0.76697173 | AA10: =STDEV('Biochem Summary'!U236:U240) -> 0.9690947 | AB10: 5
C11: 0.5 | D11: D1 | K11: =AVERAGE('Biochem Summary'!G242:G246) -> 1.7146341 | L11: =STDEV('Biochem Summary'!G242:G246) -> 0.41271075 | M11: 5 | N11: =AVERAGE('Biochem Summary'!I242:I246) -> 92.486726 | O11: =STDEV('Biochem Summary'!I242:I246) -> 27.798286 | P11: =COUNT('Biochem Summary'!I242:I246) -> 5 | Q11: =AVERAGE('Biochem Summary'!L242:L246) -> 327.86376 | R11: =STDEV('Biochem Summary'!L242:L246) -> 47.470579 | S11: =COUNT('Biochem Summary'!L242:L246) -> 5 | T11: =AVERAGE('Biochem Summary'!O242:O246) -> 213.79599 | U11: =STDEV('Biochem Summary'!O242:O246) -> 11.461004 | V11: 5 | W11: =AVERAGE('Biochem Summary'!R242:R246) -> 0.00041689855 | X11: =STDEV('Biochem Summary'!R242:R246) -> 0.00023957863 | Y11: =COUNT('Biochem Summary'!R242:R246) -> 5 | Z11: =AVERAGE('Biochem Summary'!U242:U246) -> 2.1019503 | AA11: =STDEV('Biochem Summary'!U242:U246) -> 1.1957712 | AB11: =COUNT('Biochem Summary'!U242:U246) -> 5
D12: D7 | K12: =AVERAGE('Biochem Summary'!G247:G252) -> 1.7403628 | L12: =STDEV('Biochem Summary'!G247:G252) -> 0.15544875 | M12: =COUNT('Biochem Summary'!G247:G252) -> 6 | N12: =AVERAGE('Biochem Summary'!I247:I255) -> 50.060703 | O12: =STDEV('Biochem Summary'!I247:I255) -> 16.681632 | P12: =COUNT('Biochem Summary'!I247:I255) -> 9 | Q12: =AVERAGE('Biochem Summary'!L247:L255) -> 320.97551 | R12: =STDEV('Biochem Summary'!L247:L255) -> 52.127426 | S12: =COUNT('Biochem Summary'!L247:L255) -> 9 | T12: =AVERAGE('Biochem Summary'!O247:O255) -> 224.80546 | U12: =STDEV('Biochem Summary'!O247:O255) -> 17.447427 | V12: =COUNT('Biochem Summary'!O247:O255) -> 9 | W12: =AVERAGE('Biochem Summary'!R247:R252) -> 0.00087163256 | X12: =STDEV('Biochem Summary'!R247:R252) -> 0.00039399988 | Y12: =COUNT('Biochem Summary'!R247:R252) -> 6 | Z12: =AVERAGE('Biochem Summary'!U247:U252) -> 6.4126147 | AA12: =STDEV('Biochem Summary'!U247:U252) -> 2.7605894 | AB12: =COUNT('Biochem Summary'!U247:U252) -> 6
C13: 50%-1hr | D13: D1 | K13: =AVERAGE('Biochem Summary'!G257:G266) -> 1.4985618 | L13: =STDEV('Biochem Summary'!G257:G266) -> 0.12520391 | M13: =COUNT('Biochem Summary'!G257:G266) -> 10 | N13: =AVERAGE('Biochem Summary'!I257:I266) -> 98.459168 | O13: =STDEV('Biochem Summary'!I257:I266) -> 37.815314 | P13: =COUNT('Biochem Summary'!I257:I266) -> 10 | Q13: =AVERAGE('Biochem Summary'!L257:L266) -> 461.4624 | R13: =STDEV('Biochem Summary'!L257:L266) -> 41.86764 | S13: 10 | T13: =AVERAGE('Biochem Summary'!O257:O266) -> 224.61794 | U13: =STDEV('Biochem Summary'!O257:O266) -> 9.9681121 | V13: =COUNT('Biochem Summary'!O257:O266) -> 5 | W13: =AVERAGE('Biochem Summary'!R257:R266) -> 0.00051703621 | X13: =STDEV('Biochem Summary'!R257:R266) -> 0.00014644894 | Y13: 10 | Z13: =AVERAGE('Biochem Summary'!U257:U266) -> 1.8282355 | AA13: =STDEV('Biochem Summary'!U257:U266) -> 0.53797586 | AB13: 10
D14: D7 | K14: =AVERAGE('Biochem Summary'!G267:G282) -> 2.1239083 | L14: =STDEV('Biochem Summary'!G267:G282) -> 0.35764121 | M14: =COUNT('Biochem Summary'!G267:G282) -> 14 | N14: =AVERAGE('Biochem Summary'!I267:I282) -> 54.978423 | O14: =STDEV('Biochem Summary'!I267:I282) -> 31.595828 | P14: =COUNT('Biochem Summary'!I267:I282) -> 15 | Q14: =AVERAGE('Biochem Summary'!L267:L282) -> 518.34689 | R14: =STDEV('Biochem Summary'!L267:L282) -> 144.98218 | S14: =COUNT('Biochem Summary'!L267:L282) -> 15 | T14: =AVERAGE('Biochem Summary'!O267:O282) -> 157.42433 | U14: =STDEV('Biochem Summary'!O267:O282) -> 22.863957 | V14: =COUNT('Biochem Summary'!O267:O282) -> 11 | W14: =AVERAGE('Biochem Summary'!R267:R282) -> 0.00062925718 | X14: =STDEV('Biochem Summary'!R267:R282) -> 0.00022681835 | Y14: =COUNT('Biochem Summary'!R267:R282) -> 15 | Z14: =AVERAGE('Biochem Summary'!U267:U282) -> 6.8719653 | AA14: =STDEV('Biochem Summary'!U267:U282) -> 4.6264554 | AB14: =COUNT('Biochem Summary'!U267:U282) -> 15
C15: AI | D15: D1 | E15: 29.269726 | F15: 5.5703797 | G15: 4 | H15: 29.269726 | I15: 5.3427392 | J15: 8 | K15: 1.2283951 | L15: 0.30505946 | M15: 6 | N15: 168.75377 | O15: 21.459116 | P15: 15 | Q15: 541.31632 | R15: 66.380663 | S15: 15 | T15: 218.00681 | U15: 14.928957 | V15: 15 | W15: 0.0083860996 | X15: 0.0021818107 | Y15: 5 | Z15: 3.4244622 | AA15: 0.96270111 | AB15: 5 | AC15: 0.0081070354 | AD15: 0.0032881141 | AE15: 4 | AF15: 2532.3333 | AG15: 690.22412 | AH15: 3 | AI15: 0.003056 | AJ15: 0.0015890274 | AK15: 3 | AL15: 3.3839267 | AM15: 0.7201856 | AN15: 3 | AO15: 1.8252815 | AP15: 0.085454427 | AQ15: 3 | AR15: 34.359469 | AS15: 9.1701703 | AT15: 3 | AU15: 0.93681481 | AV15: 0.013556163 | AW15: 3 | AX15: 87.57 | AY15: 9.7814865 | AZ15: 3 | BA15: 0.99207407 | BB15: 0.0039601929 | BC15: 3 | BG15: 3.6166499 | BH15: 0.57798006 | BI15: 15
D16: D7 | E16: 28.728127 | F16: 4.715431 | G16: 4 | H16: 28.728127 | I16: 7.5141947 | J16: 8 | K16: =AVERAGE('Biochem Summary'!G78:G101) -> 2.0558081 | L16: =STDEV('Biochem Summary'!G78:G101) -> 0.29185534 | M16: =COUNT('Biochem Summary'!G78:G101) -> 11 | N16: =AVERAGE('Biochem Summary'!I78:I101) -> 79.245452 | O16: =STDEV('Biochem Summary'!I78:I101) -> 25.151716 | P16: =COUNT('Biochem Summary'!I78:I101) -> 24 | Q16: =AVERAGE('Biochem Summary'!L78:L101) -> 544.5202 | R16: =STDEV('Biochem Summary'!L78:L101) -> 112.38185 | S16: =COUNT('Biochem Summary'!L78:L101) -> 24 | T16: =AVERAGE('Biochem Summary'!O78:O101) -> 175.98521 | U16: =STDEV('Biochem Summary'!O78:O101) -> 27.823333 | V16: =COUNT('Biochem Summary'!O78:O101) -> 16 | W16: =AVERAGE('Biochem Summary'!R78:R101) -> 0.0026616624 | X16: =STDEV('Biochem Summary'!R78:R101) -> 0.0033394463 | Y16: =COUNT('Biochem Summary'!R78:R101) -> 18 | Z16: =AVERAGE('Biochem Summary'!U78:U101) -> 8.8195288 | AA16: =STDEV('Biochem Summary'!U78:U101) -> 2.7309068 | AB16: =COUNT('Biochem Summary'!U78:U101) -> 18 | AC16: 0.097025408 | AD16: 0.026228716 | AE16: 5 | AF16: 2136.9 | AG16: 520.46324 | AH16: 4 | AI16: 0.003227 | AJ16: 0.00045494175 | AK16: 4 | AL16: 3.6647318 | AM16: 0.53069818 | AN16: 4 | AO16: 1.8572762 | AP16: 0.072707136 | AQ16: 4 | AR16: 30.272814 | AS16: 1.5134509 | AT16: 4 | AU16: 0.93333333 | AV16: 0.0027216553 | AW16: 4 | AX16: 90.463472 | AY16: 1.0957117 | AZ16: 4 | BA16: 0.9805 | BB16: 0.012273126 | BC16: 4 | BD16: 0.29791305 | BE16: 0.019185382 | BF16: 5 | BG16: 3.6765525 | BH16: 0.26593137 | BI16: 16 | BJ16: 40.4151 | BK16: 16.031992 | BL16: 8 | BM16: 85.750737 | BN16: 25.850142 | BO16: 8 | BP16: 5.942925 | BQ16: 2.0710065 | BR16: 8 | BS16: 12.255063 | BT16: 4.0396714 | BU16: 8 | BV16: 0.236225 | BW16: 0.1335527 | BX16: 8
D17: D7-unload | E17: 36.192699 | F17: 7.8084947 | G17: 4 | H17: 36.192699 | I17: 9.7747101 | J17: 8 | K17: =AVERAGE('Biochem Summary'!G102:G131) -> 2.1052947 | L17: =STDEV('Biochem Summary'!G33:G102) -> 0.60044979 | M17: =COUNT('Biochem Summary'!G102:G131) -> 15 | N17: =AVERAGE('Biochem Summary'!I102:I131) -> 66.842175 | O17: =STDEV('Biochem Summary'!I102:I131) -> 20.270251 | P17: =COUNT('Biochem Summary'!I102:I131) -> 5 | Q17: =AVERAGE('Biochem Summary'!L102:L131) -> 337.61039 | R17: =STDEV('Biochem Summary'!L93:L131) -> 187.90645 | S17: =COUNT('Biochem Summary'!L102:L131) -> 10 | T17: =AVERAGE('Biochem Summary'!O102:O131) -> 173.28957 | U17: =STDEV('Biochem Summary'!O102:O131) -> 12.179805 | V17: =COUNT('Biochem Summary'!O102:O131) -> 10 | W17: =AVERAGE('Biochem Summary'!R102:R131) -> 0.00064434414 | X17: =STDEV('Biochem Summary'!R102:R131) -> 0.00036625593 | Y17: =COUNT('Biochem Summary'!R102:R131) -> 10 | Z17: =AVERAGE('Biochem Summary'!U102:U131) -> 3.5517875 | AA17: =STDEV('Biochem Summary'!U108:U131) -> 3.7552936 | AB17: =COUNT('Biochem Summary'!U108:U131) -> 9 | AC17: 0.045634447 | AD17: 0.019787543 | AE17: 4
B18: 24m-male | D18: D0 | E18: 38.28823 | F18: 12.790351 | G18: 4 | H18: 38.28823 | I18: 15.324829 | J18: 8 | K18: 1.1545075 | L18: 0.21537649 | M18: 8 | N18: 154.68957 | O18: 41.809467 | P18: 7 | Q18: 435.63999 | R18: 65.645768 | S18: 6 | T18: 180.42607 | U18: 12.322201 | V18: 6 | AF18: 1913.5 | AG18: 603.16208 | AH18: 2 | AI18: 0.002921 | AJ18: 0.00011172287 | AK18: 2 | AL18: 0.20529449 | AM18: 0.0018264083 | AN18: 2 | AO18: 1.8583289 | AP18: 0.10242087 | AQ18: 3 | AR18: 25.841027 | AS18: 4.1730647 | AT18: 3 | AU18: 0.928 | AV18: 0.0072111026 | AW18: 3 | AX18: 90.325556 | AY18: 3.035853 | AZ18: 3 | BA18: 0.9725 | BB18: 0.0091666667 | BC18: 3
C19: 0.05 | D19: D1 | K19: =AVERAGE('Biochem Summary'!G138:G148) -> 1.2583504 | L19: =STDEV('Biochem Summary'!G138:G148) -> 0.061301748 | M19: =COUNT('Biochem Summary'!G138:G148) -> 11 | N19: =AVERAGE('Biochem Summary'!I139:I148) -> 70.507213 | O19: =STDEV('Biochem Summary'!I139:I148) -> 23.358749 | P19: =COUNT('Biochem Summary'!I138:I148) -> 10 | Q19: =AVERAGE('Biochem Summary'!L139:L148) -> 401.87166 | R19: =STDEV('Biochem Summary'!L139:L148) -> 57.893788 | S19: =COUNT('Biochem Summary'!L138:L148) -> 10 | T19: =AVERAGE('Biochem Summary'!O139:O143) -> 182.54364 | U19: =STDEV('Biochem Summary'!O139:O143) -> 37.525575 | V19: 5 | W19: =AVERAGE('Biochem Summary'!R139:R148) -> 0.0015262554 | X19: =STDEV('Biochem Summary'!R139:R148) -> 0.0016552749 | Y19: 10 | Z19: =AVERAGE('Biochem Summary'!U139:U148) -> 1.3224863 | AA19: =STDEV('Biochem Summary'!U139:U148) -> 0.4419584 | AB19: 10
D20: D7 | K20: =AVERAGE('Biochem Summary'!G160:G171) -> 2.6467639 | L20: =STDEV('Biochem Summary'!G160:G171) -> 0.37787302 | M20: =COUNT('Biochem Summary'!G160:G166) -> 7 | N20: =AVERAGE('Biochem Summary'!I160:I171) -> 30.06435 | O20: =STDEV('Biochem Summary'!I160:I171) -> 8.4609926 | P20: =COUNT('Biochem Summary'!K160:K171) -> 10 | Q20: =AVERAGE('Biochem Summary'!L160:L171) -> 422.93606 | R20: =STDEV('Biochem Summary'!L160:L171) -> 93.709446 | S20: =COUNT('Biochem Summary'!L160:L171) -> 10 | T20: =AVERAGE('Biochem Summary'!O161:O166) -> 150.86989 | U20: =STDEV('Biochem Summary'!O161:O166) -> 11.097124 | V20: 6 | W20: =AVERAGE('Biochem Summary'!R161:R166) -> 0.00089044864 | X20: =STDEV('Biochem Summary'!R161:R166) -> 0.00043620044 | Y20: =COUNT('Biochem Summary'!R161:R166) -> 6 | Z20: =AVERAGE('Biochem Summary'!U161:U166) -> 0.89187519 | AA20: =STDEV('Biochem Summary'!U161:U166) -> 0.28714684 | AB20: =COUNT('Biochem Summary'!U161:U166) -> 6
C21: 0.15 | D21: D1 | K21: =AVERAGE('Biochem Summary'!G149:G159) -> 1.5449898 | L21: =STDEV('Biochem Summary'!G149:G159) -> 0.13039757 | M21: =COUNT('Biochem Summary'!G149:G159) -> 6 | N21: =AVERAGE('Biochem Summary'!I149:I159) -> 73.936742 | O21: =STDEV('Biochem Summary'!I149:I159) -> 20.507167 | P21: =COUNT('Biochem Summary'!I149:I159) -> 11 | Q21: =AVERAGE('Biochem Summary'!L149:L159) -> 413.57951 | R21: =STDEV('Biochem Summary'!L149:L159) -> 83.914014 | S21: =COUNT('Biochem Summary'!K149:K159) -> 11 | T21: =AVERAGE('Biochem Summary'!O149:O154) -> 174.10143 | U21: =STDEV('Biochem Summary'!O149:O154) -> 37.23204 | V21: 6 | W21: =AVERAGE('Biochem Summary'!R149:R154) -> 0.0013206986 | X21: =STDEV('Biochem Summary'!R149:R154) -> 0.0001608061 | Y21: 6 | Z21: =AVERAGE('Biochem Summary'!U149:U154) -> 2.7372694 | AA21: =STDEV('Biochem Summary'!U149:U154) -> 0.75867488 | AB21: 6
D22: D7 | K22: =AVERAGE('Biochem Summary'!G172:G183) -> 2.253565 | L22: =STDEV('Biochem Summary'!G172:G183) -> 0.69397144 | M22: =COUNT('Biochem Summary'!G172:G183) -> 10 | N22: =AVERAGE('Biochem Summary'!I172:I183) -> 32.988537 | O22: =STDEV('Biochem Summary'!I172:I183) -> 14.402901 | P22: =COUNT('Biochem Summary'!K172:K183) -> 10 | Q22: =AVERAGE('Biochem Summary'!L172:L183) -> 382.05304 | R22: =STDEV('Biochem Summary'!L172:L183) -> 96.821043 | S22: =COUNT('Biochem Summary'!L172:L183) -> 10 | T22: =AVERAGE('Biochem Summary'!O172:O183) -> 164.04631 | U22: =STDEV('Biochem Summary'!O172:O183) -> 19.972562 | V22: =COUNT('Biochem Summary'!O172:O183) -> 10 | W22: =AVERAGE('Biochem Summary'!R172:R183) -> 0.00040235828 | X22: =STDEV('Biochem Summary'!R172:R183) -> 0.00021383201 | Y22: =COUNT('Biochem Summary'!R172:R183) -> 10 | Z22: =AVERAGE('Biochem Summary'!U172:U183) -> 3.8632872 | AA22: =STDEV('Biochem Summary'!U172:U183) -> 3.421718 | AB22: =COUNT('Biochem Summary'!U172:U183) -> 10
C23: 0.5 | D23: D1 | K23: =AVERAGE('Biochem Summary'!G283:G287) -> 1.3881579 | L23: =STDEV('Biochem Summary'!G283:G287) -> 0.12816289 | M23: =COUNT('Biochem Summary'!G283:G287) -> 5 | N23: =AVERAGE('Biochem Summary'!I283:I287) -> 84.136365 | O23: =STDEV('Biochem Summary'!I283:I287) -> 35.932278 | P23: =COUNT('Biochem Summary'!I283:I287) -> 5 | Q23: =AVERAGE('Biochem Summary'!L283:L287) -> 408.64451 | R23: =STDEV('Biochem Summary'!L283:L287) -> 64.657861 | S23: =COUNT('Biochem Summary'!L283:L287) -> 5 | T23: =AVERAGE('Biochem Summary'!O283:O287) -> 189.16382 | U23: =STDEV('Biochem Summary'!O283:O287) -> 19.490712 | V23: =COUNT('Biochem Summary'!O283:O287) -> 5 | W23: =AVERAGE('Biochem Summary'!R283:R287) -> 0.00026827132 | X23: =STDEV('Biochem Summary'!R283:R287) -> 0.0001035908 | Y23: =COUNT('Biochem Summary'!R283:R287) -> 5 | Z23: =AVERAGE('Biochem Summary'!U283:U287) -> 1.684711 | AA23: =STDEV('Biochem Summary'!U283:U287) -> 0.4969208 | AB23: =COUNT('Biochem Summary'!U283:U287) -> 5
D24: D7 | K24: =AVERAGE('Biochem Summary'!G288:G302) -> 2.5448954 | L24: =STDEV('Biochem Summary'!G288:G302) -> 0.65734216 | M24: =COUNT('Biochem Summary'!G288:G302) -> 7 | N24: =AVERAGE('Biochem Summary'!I288:I302) -> 55.476131 | O24: =STDEV('Biochem Summary'!I288:I302) -> 21.743477 | P24: =COUNT('Biochem Summary'!I288:I302) -> 9 | Q24: =AVERAGE('Biochem Summary'!L288:L302) -> 474.69437 | R24: =STDEV('Biochem Summary'!L288:L302) -> 60.603723 | S24: =COUNT('Biochem Summary'!L288:L302) -> 14 | T24: =AVERAGE('Biochem Summary'!O288:O302) -> 148.77605 | U24: =STDEV('Biochem Summary'!O288:O302) -> 32.647081 | V24: =COUNT('Biochem Summary'!O288:O302) -> 14 | W24: =AVERAGE('Biochem Summary'!R288:R302) -> 0.00093714201 | X24: =STDEV('Biochem Summary'!R288:R302) -> 0.00062659054 | Y24: =COUNT('Biochem Summary'!R288:R302) -> 13 | Z24: =AVERAGE('Biochem Summary'!U288:U302) -> 6.2890838 | AA24: =STDEV('Biochem Summary'!U288:U302) -> 1.8573301 | AB24: =COUNT('Biochem Summary'!U288:U302) -> 7
C25: 50%-1hr | D25: D1
D26: D7 | K26: =AVERAGE('Biochem Summary'!G303:G312) -> 1.9579832 | L26: =STDEV('Biochem Summary'!G303:G312) -> 0.28726365 | M26: =COUNT('Biochem Summary'!G303:G312) -> 8 | N26: =AVERAGE('Biochem Summary'!I303:I312) -> 88.044097 | O26: =STDEV('Biochem Summary'!I303:I312) -> 12.38387 | P26: =COUNT('Biochem Summary'!I303:I312) -> 10 | Q26: =AVERAGE('Biochem Summary'!L303:L312) -> 479.55317 | R26: =STDEV('Biochem Summary'!L303:L312) -> 48.127442 | S26: =COUNT('Biochem Summary'!L303:L312) -> 10 | T26: =AVERAGE('Biochem Summary'!O303:O312) -> 156.52777 | U26: =STDEV('Biochem Summary'!O303:O312) -> 10.024848 | V26: =COUNT('Biochem Summary'!O303:O312) -> 10 | W26: =AVERAGE('Biochem Summary'!R303:R312) -> 0.00048095661 | X26: =STDEV('Biochem Summary'!R303:R312) -> 5.2354922e-05 | Y26: =COUNT('Biochem Summary'!R303:R312) -> 10 | Z26: =AVERAGE('Biochem Summary'!U303:U312) -> 6.6312785 | AA26: =STDEV('Biochem Summary'!U303:U312) -> 1.9225769 | AB26: =COUNT('Biochem Summary'!U303:U312) -> 10
C27: AI | D27: D1 | E27: 31.741872 | F27: 2.6081265 | G27: 4 | H27: 31.741872 | I27: 5.0305824 | J27: 8 | K27: 1.3432099 | L27: 0.064178535 | M27: 6 | N27: 119.46441 | O27: 16.947486 | P27: 16 | Q27: 432.60945 | R27: 43.333092 | S27: 16 | T27: 221.22995 | U27: 21.56335 | V27: 16 | W27: 0.0013370898 | X27: 0.0003714387 | Y27: 5 | Z27: 2.3635957 | AA27: 0.48243173 | AB27: 5 | AC27: 0.0052279519 | AD27: 0.0013645067 | AE27: 5 | AF27: 2235.9556 | AG27: 444.15443 | AH27: 3 | AI27: 0.002793 | AJ27: 0.00013114496 | AK27: 3 | AL27: 4.4816067 | AM27: 0.4520661 | AN27: 3 | AO27: 1.8862592 | AP27: 0.03278204 | AQ27: 3 | AR27: 24.89939 | AS27: 5.4788361 | AT27: 3 | AU27: 0.92259259 | AV27: 0.0077843887 | AW27: 3 | AX27: 91.539259 | AY27: 2.0395565 | AZ27: 3 | BA27: 0.97796296 | BB27: 0.013521055 | BC27: 3 | BG27: 3.9072863 | BH27: 0.6082638 | BI27: 16
D28: D7 | E28: 21.113805 | F28: 17.0207 | G28: 4 | H28: 24.118286 | I28: 15.520242 | J28: 7 | K28: =AVERAGE('Biochem Summary'!G184:G208) -> 1.7552269 | L28: =STDEV('Biochem Summary'!G184:G208) -> 0.21339975 | M28: =COUNT('Biochem Summary'!G184:G208) -> 10 | N28: =AVERAGE('Biochem Summary'!I178:I208) -> 47.405189 | O28: =STDEV('Biochem Summary'!I184:I208) -> 19.397951 | P28: =COUNT('Biochem Summary'!I184:I208) -> 24 | Q28: =AVERAGE('Biochem Summary'!L184:L208) -> 455.24976 | R28: =STDEV('Biochem Summary'!L184:L207) -> 126.25868 | S28: =COUNT('Biochem Summary'!L184:L208) -> 23 | T28: =AVERAGE('Biochem Summary'!O184:O208) -> 181.33754 | U28: =STDEV('Biochem Summary'!O184:O208) -> 24.870569 | V28: =COUNT('Biochem Summary'!O184:O208) -> 20 | W28: =AVERAGE('Biochem Summary'!R184:R208) -> 0.0030210272 | X28: =STDEV('Biochem Summary'!R184:R208) -> 0.0024848992 | Y28: =COUNT('Biochem Summary'!R184:R208) -> 9 | Z28: =AVERAGE('Biochem Summary'!U184:U208) -> 6.3357126 | AA28: =STDEV('Biochem Summary'!U184:U208) -> 1.6824496 | AB28: =COUNT('Biochem Summary'!U184:U208) -> 9 | AC28: 0.069879072 | AD28: 0.043344033 | AE28: 5 | AF28: 2381.1833 | AG28: 222.87654 | AH28: 3 | AI28: 0.0031946667 | AJ28: 5.5193599e-05 | AK28: 3 | AL28: 5.1994943 | AM28: 0.2839712 | AN28: 3 | AO28: 1.8616869 | AP28: 0.049678334 | AQ28: 3 | AR28: 30.650114 | AS28: 5.7164216 | AT28: 3 | AU28: 0.932 | AV28: 0.0073105707 | AW28: 3 | AX28: 97.771296 | AY28: 4.9827751 | AZ28: 3 | BA28: 0.97614815 | BB28: 0.019811561 | BC28: 3 | BD28: 0.22776669 | BE28: 0.028755695 | BF28: 4 | BG28: 3.4282391 | BH28: 0.24681788 | BI28: 20 | BJ28: 24.626617 | BK28: 7.0516435 | BL28: 6 | BM28: 96.4336 | BN28: 59.236233 | BO28: 6 | BP28: 5.1546167 | BQ28: 2.343815 | BR28: 6 | BS28: 11.60475 | BT28: 6.0586917 | BU28: 6 | BV28: 0.1871 | BW28: 0.075430259 | BX28: 6
D29: D7-Unload | E29: =[1]Viability!S40 -> 34.89994 | F29: =[1]Viability!AA8 -> 6.2580261 | G29: =[1]Viability!AB8 -> 6 | H29: =[1]Viability!Z8 -> 35.634215 | I29: =STDEV([1]Viability!S29:S39) -> 11.5301 | J29: 10 | K29: =AVERAGE('Biochem Summary'!G209:G229) -> 2.1213533 | L29: =STDEV('Biochem Summary'!G209:G229) -> 0.35374176 | M29: =COUNT('Biochem Summary'!G209:G229) -> 10 | N29: =AVERAGE('Biochem Summary'!I209:I229) -> 52.109898 | O29: =STDEV('Biochem Summary'!I209:I229) -> 23.096319 | P29: =COUNT('Biochem Summary'!I209:I229) -> 18 | Q29: =AVERAGE('Biochem Summary'!L209:L229) -> 448.19522 | R29: =STDEV('Biochem Summary'!L209:L229) -> 120.74733 | S29: =COUNT('Biochem Summary'!L209:L229) -> 18 | T29: =AVERAGE('Biochem Summary'!O209:O229) -> 168.5234 | U29: =STDEV('Biochem Summary'!O209:O229) -> 21.342392 | V29: =COUNT('Biochem Summary'!O209:O229) -> 12 | W29: =AVERAGE('Biochem Summary'!R209:R229) -> 0.0022048238 | X29: =STDEV('Biochem Summary'!R209:R229) -> 0.0023563722 | Y29: =COUNT('Biochem Summary'!R209:R229) -> 8 | Z29: =AVERAGE('Biochem Summary'!U209:U229) -> 4.7402149 | AA29: =STDEV('Biochem Summary'!U209:U229) -> 4.1936699 | AB29: =COUNT('Biochem Summary'!U209:U229) -> 8 | AC29: =AVERAGE('[1]Biochem Summary'!X104:X119) -> 0.0014123155 | AD29: =STDEV('[1]Biochem Summary'!X104:X119) -> 0.0002408662 | AE29: =COUNT('[1]Biochem Summary'!X104:X119) -> 3
E34: 14 | F34: 13
E35: 9 | F35: 18
E36: 10
E37: =SUM(E34:F36) -> 64
H53: s

Sheet Biochem Summary
A1: Table of Contents | B1: Group | C1: Experiment | D1: Sample | E1: Wet weight | F1: Dry Weight | G1: Alamar Blue | H1: Picogreen | J1: DMMB | M1: OHP | P1: Proline Incorporation | S1: S35 Incorporation | V1: Thymidine Incorporation | Y1: Wet/Dry
H2: Raw | I2: Picogreen (DW) | J2: Raw | K2: DNA | L2: DW | M2: Raw (ug) | N2: DNA | O2: DW (ug/mg) | P2: Raw | Q2: DNA | R2: DW | S2: Raw | T2: DNA | U2: DW | V2: Raw | W2: DNA | X2: DW
B3: 4m D0 | C3: AI8 | D3: X1 | E3: 1.86 | F3: 0.475 | G3: 1.2653061 | H3: 71.265763 | I3: 150.03319 | J3: 252.6725 | K3: 3545.4963 | L3: 531.94211 | M3: 89.528755 | N3: 1256.266 | O3: 188.48159 | Y3: =E3/F3 -> 3.9157895
D4: X2 | E4: 1.88 | G4: 1.3265306
D5: X3 | E5: 1.7666667 | F5: 0.475 | G5: 1.3061224 | H5: 73.461063 | I5: 154.65487 | J5: 288.77 | K5: 3930.9259 | L5: 607.93684 | M5: 79.833319 | N5: 1086.7433 | O5: 168.07015 | Y5: =E5/F5 -> 3.7192982
D6: X4 | E6: 1.59 | F6: 0.445 | G6: 1.2380952 | H6: 106.39056 | I6: 239.07992 | J6: 262.2985 | K6: 2465.4301 | L6: 589.43483 | M6: 86.147926 | N6: 809.73277 | O6: 193.59084 | Y6: =E6/F6 -> 3.5730337
D7: X5 | E7: 2.5366667 | G7: 1.2108844
D8: X6 | E8: 1.41 | F8: 0.31 | G8: 1.3129252 | H8: 50.410413 | I8: 162.61424 | J8: 255.079 | K8: 5060.0458 | L8: 822.83548 | M8: 70.556994 | N8: 1399.6512 | O8: 227.60321 | Y8: =E8/F8 -> 4.5483871
C9: AI30 | D9: X1 | E9: 2.9733333 | F9: 0.58 | G9: 1.1153846 | H9: 52.829016 | I9: 91.084511 | J9: 301.2522 | K9: 5702.4003 | L9: 519.40034 | M9: 556.8424 | N9: 10540.465 | O9: 960.0731 | Y9: =E9/F9 -> 5.1264368
D10: X2 | E10: 2.19 | F10: 0.63 | G10: 1.1709402 | H10: 67.752536 | I10: 107.54371 | J10: 379.8258 | K10: 5606.075 | L10: 602.8981 | M10: 528.36879 | N10: 7798.5094 | O10: 838.68062 | Y10: =E10/F10 -> 3.4761905
B11: 4m 5% D1 | C11: DC9 | D11: X1 | E11: =Weights!I29 -> 2.69 | F11: =Weights!M29 -> 0.555 | G11: ='Alamar Blue (Analysis)'!F17 -> 1.4924242 | H11: =PicoGreen!U57 -> 63.872389 | I11: =H11/F11 -> 115.08539 | J11: =DMMB!U65 -> 288.6311 | K11: =J11/H11*1000 -> 4518.8712 | L11: =J11/F11 -> 520.05604 | M11: =OHP!V57 -> 124.55912 | N11: =M11/H11*1000 -> 1950.1246 | O11: =M11/F11 -> 224.43084 | P11: =Rx!S14 -> 0.0016937932 | Q11: =P11/H11 -> 2.6518394e-05 | R11: =P11/F11 -> 0.0030518796 | S11: =Rx!W14 -> 1.3293983 | T11: =S11/H11 -> 0.020813349 | U11: =S11/F11 -> 2.3953123 | Y11: =E11/F11 -> 4.8468468
D12: X2 | E12: =Weights!I30 -> 2.095 | F12: =Weights!M30 -> 0.565 | G12: ='Alamar Blue (Analysis)'!F18 -> 1.4015152 | H12: =PicoGreen!U58 -> 82.248989 | I12: =H12/F12 -> 145.57343 | J12: =DMMB!U66 -> 270.6703 | K12: =J12/H12*1000 -> 3290.8647 | L12: =J12/F12 -> 479.06248 | M12: =OHP!V58 -> 83.066739 | N12: =M12/H12*1000 -> 1009.9424 | O12: =M12/F12 -> 147.02078 | P12: =Rx!S15 -> 0.00094202745 | Q12: =P12/H12 -> 1.1453362e-05 | R12: =P12/F12 -> 0.0016673052 | S12: =Rx!W15 -> 0.73201046 | T12: =S12/H12 -> 0.0088999326 | U12: =S12/F12 -> 1.2955937 | Y12: =E12/F12 -> 3.7079646
D13: X3 | E13: =Weights!I31 -> 2.2766667 | F13: =Weights!M31 -> 0.555 | G13: ='Alamar Blue (Analysis)'!F19 -> 1.3484848 | H13: =PicoGreen!U59 -> 70.304199 | I13: =H13/F13 -> 126.67423 | J13: =DMMB!U67 -> 259.4448 | K13: =J13/H13*1000 -> 3690.3173 | L13: =J13/F13 -> 467.46811 | M13: =OHP!V59 -> 96.562014 | N13: =M13/H13*1000 -> 1373.4886 | O13: =M13/F13 -> 173.98561 | P13: =Rx!S16 -> 0.0011972566 | Q13: =P13/H13 -> 1.7029659e-05 | R13: =P13/F13 -> 0.002157219 | S13: =Rx!W16 -> 0.82877046 | T13: =S13/H13 -> 0.011788349 | U13: =S13/F13 -> 1.4932801 | Y13: =E13/F13 -> 4.1021021
D14: X4 | E14: =Weights!I32 -> 2.0366667 | F14: =Weights!M32 -> 0.48 | G14: ='Alamar Blue (Analysis)'!F20 -> 1.5606061 | H14: =PicoGreen!U60 -> 72.601274 | I14: =H14/F14 -> 151.25266 | J14: =DMMB!U68 -> 266.1801 | K14: =J14/H14*1000 -> 3666.3282 | L14: =J14/F14 -> 554.54187 | M14: =OHP!V60 -> 88.733263 | N14: =M14/H14*1000 -> 1222.1998 | O14: =M14/F14 -> 184.86097 | P14: =Rx!S17 -> 0.0016473879 | Q14: =P14/H14 -> 2.2690895e-05 | R14: =P14/F14 -> 0.0034320581 | S14: =Rx!W17 -> 1.4766418 | T14: =S14/H14 -> 0.020339062 | U14: =S14/F14 -> 3.0763371 | Y14: =E14/F14 -> 4.2430556
D15: X5 | E15: =Weights!I33 -> 1.85 | F15: =Weights!M33 -> 0.45 | G15: ='Alamar Blue (Analysis)'!F21 -> 1.5151515 | H15: =PicoGreen!U61 -> 52.387014 | I15: =H15/F15 -> 116.41559 | J15: =DMMB!U69 -> 241.484 | K15: =J15/H15*1000 -> 4609.6156 | L15: =J15/F15 -> 536.63111 | M15: =OHP!V61 -> 84.818888 | N15: =M15/H15*1000 -> 1619.0823 | O15: =M15/F15 -> 188.48642 | P15: =Rx!S18 -> 0.0014153614 | Q15: =P15/H15 -> 2.701741e-05 | R15: =P15/F15 -> 0.0031452476 | S15: =Rx!W18 -> 1.2873287 | T15: =S15/H15 -> 0.024573432 | U15: =S15/F15 -> 2.8607305 | Y15: =E15/F15 -> 4.1111111
D16: X6 | E16: =Weights!I34 -> 2.2433333 | F16: =Weights!M34 -> 0.51 | G16: ='Alamar Blue (Analysis)'!F22 -> 1.4090909 | H16: =PicoGreen!U62 -> 52.846429 | I16: =H16/F16 -> 103.62045 | J16: =DMMB!U70 -> 302.1017 | K16: =J16/H16*1000 -> 5716.5962 | L16: =J16/F16 -> 592.35627 | M16: =OHP!V62 -> 58.163857 | N16: =M16/H16*1000 -> 1100.6204 | O16: =M16/F16 -> 114.04678 | P16: =Rx!S19 -> 0.0015220936 | Q16: =P16/H16 -> 2.8802203e-05 | R16: =P16/F16 -> 0.0029844973 | S16: =Rx!W19 -> 1.7122314 | T16: =S16/H16 -> 0.032400133 | U16: =S16/F16 -> 3.3573164 | Y16: =E16/F16 -> 4.3986928
C17: DC12 | D17: X1 | E17: =Weights!I50 -> 1.82 | F17: =Weights!M50 -> 0.53 | G17: {='Alamar Blue (Analysis)'!F24:F28} -> 1.390625 | H17: =PicoGreen!AY46 -> 48.394309 | I17: =H17/F17 -> 91.310017 | J17: =DMMB!AY54 -> 298.1507 | K17: =J17/H17*1000 -> 6160.8628 | L17: =J17/F17 -> 562.54849 | M17: =OHP!AZ46 -> 168.23775 | N17: =M17/H17*1000 -> 3476.3953 | O17: =M17/F17 -> 317.42972 | P17: =Rx!AQ3 -> 2.1633022e-05 | Q17: =P17/H17 -> 4.4701582e-07 | R17: =P17/F17 -> 4.0817022e-05 | S17: =Rx!AU3 -> 0.83085261 | T17: =S17/H17 -> 0.017168395 | U17: =S17/F17 -> 1.5676464 | Y17: =E17/F17 -> 3.4339623
D18: X2 | E18: =Weights!I51 -> 2.6666667 | F18: =Weights!M51 -> 0.68 | G18: 1.15625 | H18: =PicoGreen!AY47 -> 91.076039 | I18: =H18/F18 -> 133.93535 | J18: =DMMB!AY55 -> 350.2687 | K18: =J18/H18*1000 -> 3845.893 | L18: =J18/F18 -> 515.10103 | P18: =Rx!AQ4 -> 1.0875617e-05 | Q18: =P18/H18 -> 1.194125e-07 | R18: =P18/F18 -> 1.5993555e-05 | S18: =Rx!AU4 -> 0.38301716 | T18: =S18/H18 -> 0.0042054657 | U18: =S18/F18 -> 0.56326053 | Y18: =E18/F18 -> 3.9215686
D19: X3 | E19: =Weights!I52 -> 1.9766667 | F19: =Weights!M52 -> 0.545 | G19: 1.1770833 | H19: =PicoGreen!AY48 -> 58.944849 | I19: =H19/F19 -> 108.15569 | J19: =DMMB!AY56 -> 253.8504 | K19: =J19/H19*1000 -> 4306.5748 | L19: =J19/F19 -> 465.78055 | M19: =OHP!AZ47 -> 161.92769 | N19: =M19/H19*1000 -> 2747.105 | O19: =M19/F19 -> 297.11502 | P19: =Rx!AQ5 -> 1.7850198e-05 | Q19: =P19/H19 -> 3.0282881e-07 | R19: =P19/F19 -> 3.2752657e-05 | S19: =Rx!AU5 -> 0.68353832 | T19: =S19/H19 -> 0.011596235 | U19: =S19/F19 -> 1.2541988 | Y19: =E19/F19 -> 3.6269113
D20: X4 | E20: =Weights!I53 -> 1.7133333 | F20: =Weights!M53 -> 0.505 | G20: 1.140625 | H20: =PicoGreen!AY49 -> 45.516889 | I20: =H20/F20 -> 90.132453 | J20: =DMMB!AY57 -> 219.9737 | K20: =J20/H20*1000 -> 4832.7929 | L20: =J20/F20 -> 435.59149 | M20: =OHP!AZ48 -> 155.03169 | N20: =M20/H20*1000 -> 3406.0256 | O20: =M20/F20 -> 306.99344 | P20: =Rx!AQ6 -> 1.7022706e-05 | Q20: =P20/H20 -> 3.7398658e-07 | R20: =P20/F20 -> 3.3708328e-05 | S20: =Rx!AU6 -> 0.63050518 | T20: =S20/H20 -> 0.013852115 | U20: =S20/F20 -> 1.2485251 | Y20: =E20/F20 -> 3.3927393
D21: X5 | E21: =Weights!I54 -> 1.66 | F21: =Weights!M54 -> 0.45 | G21: 1.0625 | H21: =PicoGreen!AY50 -> 57.985709 | I21: =H21/F21 -> 128.85713 | J21: =DMMB!AY58 -> 235.6091 | K21: =J21/H21*1000 -> 4063.227 | L21: =J21/F21 -> 523.57578 | M21: =OHP!AZ49 -> 46.814096 | N21: =M21/H21*1000 -> 807.33852 | O21: =M21/F21 -> 104.03133 | P21: =Rx!AQ7 -> 2.0569103e-05 | Q21: =P21/H21 -> 3.547271e-07 | R21: =P21/F21 -> 4.5709117e-05 | S21: =Rx!AU7 -> 0.71889375 | T21: =S21/H21 -> 0.012397775 | U21: =S21/F21 -> 1.5975417 | Y21: =E21/F21 -> 3.6888889
B22: 4m 15% D1 | C22: DC8 | D22: X1 | E22: =Weights!I23 -> 1.36 | F22: =Weights!M23 -> 0.395 | G22: ='Alamar Blue (Analysis)'!L17 -> 1.4417178 | H22: =PicoGreen!U51 -> 65.710049 | I22: =H22/F22 -> 166.35456 | J22: =DMMB!U59 -> 254.9546 | K22: =J22/H22*1000 -> 3879.994 | L22: =J22/F22 -> 645.45468 | M22: =OHP!V51 -> 90.85821 | N22: =M22/H22*1000 -> 1382.7141 | O22: =M22/F22 -> 230.02078 | P22: =Rx!S8 -> 0.0018275272 | Q22: =P22/H22 -> 2.7811989e-05 | R22: =P22/F22 -> 0.0046266511 | S22: =Rx!W8 -> 0.32033922 | T22: =S22/H22 -> 0.0048750415 | U22: =S22/F22 -> 0.81098536 | Y22: =E22/F22 -> 3.443038
D23: X2 | E23: =Weights!I24 -> 1.99 | F23: =Weights!M24 -> 0.47 | G23: ='Alamar Blue (Analysis)'!L18 -> 1.2944785 | H23: =PicoGreen!U52 -> 68.925954 | I23: =H23/F23 -> 146.65097 | J23: =DMMB!U60 -> 304.3468 | K23: =J23/H23*1000 -> 4415.5616 | L23: =J23/F23 -> 647.54638 | M23: =OHP!V52 -> 73.59768 | N23: =M23/H23*1000 -> 1067.7789 | O23: =M23/F23 -> 156.59081 | P23: =Rx!S9 -> 0.0012581469 | Q23: =P23/H23 -> 1.8253601e-05 | R23: =P23/F23 -> 0.0026769082 | S23: =Rx!W9 -> 1.3645619 | T23: =S23/H23 -> 0.019797504 | U23: =S23/F23 -> 2.9033231 | Y23: =E23/F23 -> 4.2340426
D24: X3 | E24: =Weights!I25 -> 1.6233333 | F24: =Weights!M25 -> 0.45 | G24: ='Alamar Blue (Analysis)'!L19 -> 1.3496933 | H24: =PicoGreen!U53 -> 76.276594 | I24: =H24/F24 -> 169.50354 | J24: =DMMB!U61 -> 272.9154 | K24: =J24/H24*1000 -> 3577.9704 | L24: =J24/F24 -> 606.47867 | M24: =OHP!V53 -> 70.838977 | N24: =M24/H24*1000 -> 928.71185 | O24: =M24/F24 -> 157.41995 | P24: =Rx!S10 -> 0.00053723789 | Q24: =P24/H24 -> 7.0432863e-06 | R24: =P24/F24 -> 0.001193862 | S24: =Rx!W10 -> 0.4867492 | T24: =S24/H24 -> 0.0063813704 | U24: =S24/F24 -> 1.0816649 | Y24: =E24/F24 -> 3.6074074
D25: X4 | E25: =Weights!I26 -> 1.815 | F25: =Weights!M26 -> 0.48 | G25: ='Alamar Blue (Analysis)'!L20 -> 1.7484663 | H25: =PicoGreen!U54 -> 60.197069 | I25: =H25/F25 -> 125.41056 | J25: =DMMB!U62 -> 279.6507 | K25: =J25/H25*1000 -> 4645.5866 | L25: =J25/F25 -> 582.60562 | M25: =OHP!V54 -> 109.57265 | N25: =M25/H25*1000 -> 1820.2323 | O25: =M25/F25 -> 228.27636 | P25: =Rx!S11 -> 0.0010836593 | Q25: =P25/H25 -> 1.8001862e-05 | R25: =P25/F25 -> 0.0022576236 | S25: =Rx!W11 -> 0.90277416 | T25: =S25/H25 -> 0.014996979 | U25: =S25/F25 -> 1.8807795 | Y25: =E25/F25 -> 3.78125
D26: X5 | E26: =Weights!I27 -> 1.4366667 | F26: =Weights!M27 -> 0.45 | G26: ='Alamar Blue (Analysis)'!L21 -> 1.3496933 | H26: =PicoGreen!U55 -> 48.252279 | I26: =H26/F26 -> 107.22729 | J26: =DMMB!U63 -> 268.4252 | K26: =J26/H26*1000 -> 5562.9538 | L26: =J26/F26 -> 596.50044 | M26: =OHP!V55 -> 75.648067 | N26: =M26/H26*1000 -> 1567.7615 | O26: =M26/F26 -> 168.10681 | P26: =Rx!S12 -> 0.0011846784 | Q26: =P26/H26 -> 2.4551761e-05 | R26: =P26/F26 -> 0.0026326187 | S26: =Rx!W12 -> 1.4602476 | T26: =S26/H26 -> 0.030262769 | U26: =S26/F26 -> 3.2449947 | Y26: =E26/F26 -> 3.1925926
D27: X6 | E27: =Weights!I28 -> 1.56 | F27: =Weights!M28 -> 0.51333333 | G27: ='Alamar Blue (Analysis)'!L22 -> 1.595092 | H27: =PicoGreen!U56 -> 40.442224 | I27: =H27/F27 -> 78.783554 | J27: =DMMB!U64 -> 299.8566 | K27: =J27/H27*1000 -> 7414.4438 | L27: =J27/F27 -> 584.13623 | M27: =OHP!V56 -> 90.671811 | N27: =M27/H27*1000 -> 2242.0085 | O27: =M27/F27 -> 176.6334 | P27: =Rx!S13 -> 0.00078978562 | Q27: =P27/H27 -> 1.9528738e-05 | R27: =P27/F27 -> 0.0015385434 | S27: =Rx!W13 -> 0.82788967 | T27: =S27/H27 -> 0.020470923 | U27: =S27/F27 -> 1.6127721 | Y27: =E27/F27 -> 3.038961
C28: DC15 | D28: X1 | E28: =Weights!I77 -> 2.3033333 | F28: =Weights!M77 -> 0.58 | H28: =PicoGreen!CC46 -> 24.449734 | I28: =H28/F28 -> 42.154714 | J28: =DMMB!CC54 -> 229.236 | K28: =J28/H28*1000 -> 9375.8075 | L28: =J28/F28 -> 395.23448 | M28: =OHP!BO46 -> 119.53683 | N28: =M28/H28*1000 -> 4889.085 | O28: =M28/F28 -> 206.09798 | P28: =Rx!BP3 -> 0.00017890055 | Q28: =P28/H28 -> 7.3170754e-06 | R28: =P28/F28 -> 0.00030844922 | S28: =Rx!BT3 -> 0.85139033 | T28: =S28/H28 -> 0.034822069 | U28: =S28/F28 -> 1.4679144
D29: X2 | E29: =Weights!I78 -> 2.1966667 | F29: =Weights!M78 -> 0.615 | H29: =PicoGreen!CC47 -> 48.197234 | I29: =H29/F29 -> 78.369486 | J29: =DMMB!CC55 -> 263.988 | K29: =J29/H29*1000 -> 5477.2438 | L29: =J29/F29 -> 429.24878 | M29: =OHP!BO47 -> 119.9772 | N29: =M29/H29*1000 -> 2489.2964 | O29: =M29/F29 -> 195.08488 | P29: =Rx!BP4 -> 0.00034950769 | Q29: =P29/H29 -> 7.2516131e-06 | R29: =P29/F29 -> 0.00056830519 | S29: =Rx!BT4 -> 1.1957026 | T29: =S29/H29 -> 0.024808531 | U29: =S29/F29 -> 1.9442319
D30: X3 | E30: =Weights!I79 -> 2.28 | H30: =PicoGreen!CC48 -> 35.373584 | J30: =DMMB!CC56 -> 237.924 | K30: =J30/H30*1000 -> 6726.036 | M30: =OHP!BO48 -> 132.84591 | N30: =M30/H30*1000 -> 3755.5117 | P30: =Rx!BP5 -> 0.00043718081 | Q30: =P30/H30 -> 1.2358963e-05 | S30: =Rx!BT5 -> 1.5212342 | T30: =S30/H30 -> 0.043004808
D31: X4 | E31: =Weights!I80 -> 2.085 | F31: =Weights!M80 -> 0.59 | H31: =PicoGreen!CC49 -> 29.199234 | I31: =H31/F31 -> 49.490227 | J31: =DMMB!CC57 -> 231.408 | K31: =J31/H31*1000 -> 7925.1394 | L31: =J31/F31 -> 392.21695 | M31: =OHP!BO49 -> 125.53081 | N31: =M31/H31*1000 -> 4299.113 | O31: =M31/F31 -> 212.76408 | P31: =Rx!BP6 -> 0.0004123006 | Q31: =P31/H31 -> 1.4120254e-05 | R31: =P31/F31 -> 0.00069881458 | S31: =Rx!BT6 -> 1.7278216 | T31: =S31/H31 -> 0.059173523 | U31: =S31/F31 -> 2.9285111
D32: X5 | E32: =Weights!I81 -> 2.03 | F32: =Weights!M81 -> 0.59 | H32: =PicoGreen!CC50 -> 36.323484 | I32: =H32/F32 -> 61.565227 | J32: =DMMB!CC58 -> 240.096 | K32: =J32/H32*1000 -> 6609.9386 | L32: =J32/F32 -> 406.94237 | M32: =OHP!BO50 -> 116.64993 | N32: =M32/H32*1000 -> 3211.4191 | O32: =M32/F32 -> 197.71175 | P32: =Rx!BP7 -> 0.00029145387 | Q32: =P32/H32 -> 8.0238414e-06 | R32: =P32/F32 -> 0.00049398962 | S32: =Rx!BT7 -> 0.90773234 | T32: =S32/H32 -> 0.024990233 | U32: =S32/F32 -> 1.5385294
B33: 4m D1 | C33: AI11 | D33: X1 | E33: 1.6766667 | F33: 0.525 | G33: 1.1481481 | H33: 105.74344 | I33: 201.41607 | J33: 323.181 | K33: 3056.2748 | L33: 615.58286 | M33: 137.4662 | N33: 1299.9975 | O33: 261.84039
D34: X2 | E34: 1.6866667 | F34: 0.48333333 | G34: 0.99074074 | H34: 94.925286 | I34: 196.39714 | J34: 319.039 | K34: 3360.9485 | L34: 660.08069 | M34: 102.10675 | N34: 1075.6538 | O34: 211.25533
D35: X3 | E35: 1.4966667 | F35: 0.51 | G35: 1.5092593 | H35: 78.440486 | I35: 153.80487 | J35: 273.477 | K35: 3486.4267 | L35: 536.22941 | M35: 112.95993 | N35: 1440.0718 | O35: 221.49007
D36: X4 | E36: 1.4533333 | F36: 0.51 | G36: 0.77777778 | H36: 86.682886 | I36: 169.96644 | J36: 287.974 | K36: 3322.1552 | L36: 564.6549 | M36: 106.75399 | N36: 1231.5463 | O36: 209.32155
D37: X5 | E37: 1.1733333 | F37: 0.475 | G37: 1.5 | H37: 93.379836 | I37: 196.58913 | J37: 312.826 | K37: 3350.038 | L37: 658.58105 | M37: 99.624367 | N37: 1066.8724 | O37: 209.73551
D38: X6 | E38: 1.6333333 | F38: 0.515 | G38: 1.4444444 | H38: 89.258636 | I38: 173.31774 | J38: 304.542 | K38: 3411.9052 | L38: 591.34369 | M38: 107.96631 | N38: 1209.5895 | O38: 209.64332
C39: AI21 | D39: PX1 | E39: 2.32 | F39: 0.59 | H39: 96.470736 | I39: 163.50972 | J39: 300.4 | K39: 3113.8977 | L39: 509.15254 | M39: 132.37391 | N39: 1372.1664 | O39: 224.36255 | P39: 0.0056085146 | Q39: 5.8136953e-05 | R39: 0.009505957 | S39: 2.828042 | T39: 0.029315024 | U39: 4.7932915
D40: PX2 | E40: 2.6666667 | F40: 0.60333333 | H40: 83.076836 | I40: 137.69641 | J40: 271.406 | K40: 3266.9275 | L40: 449.8442 | M40: 128.31515 | N40: 1544.5358 | O40: 212.67704 | P40: 0.0029268478 | Q40: 3.5230612e-05 | R40: 0.004851129 | S40: 1.2849744 | T40: 0.015467301 | U40: 2.1297918
...

Sheet Chronological Biochem
B1: Biochem Date | C1: Experiment | D1: Sample | E1: Picogreen | G1: Proline Incorporation | J1: S35 Incorporation
E2: Raw | F2: Picogreen (DW) | G2: Raw | H2: DNA | I2: DW | J2: Raw | K2: DNA | L2: DW | S2: Pico | T2: Proline | U2: S35
B3: 1 | C3: AI14 | D3: X1 | E3: 60.289263 | F3: 114.83669 | R3: 1 | S3: =AVERAGE(F3:F8) -> 100.52888
D4: X2 | E4: 36.140963 | F4: 62.312006 | R4: 2 | S4: =AVERAGE(F9:F14) -> 95.118572 | T4: =AVERAGE(I9:I14) -> 0.0012092016 | U4: =AVERAGE(L9:L14) -> 6.2953928
D5: X3 | E5: 44.922163 | F5: 91.677884 | R5: 3 | S5: =AVERAGE(F15:F22) -> 72.261723 | T5: =AVERAGE(I15:I22) -> 0.00018575655 | U5: =AVERAGE(L15:L22) -> 0.18813374
D6: X4 | E6: 47.117463 | F6: 85.668115 | R6: 4 | S6: =AVERAGE(F23:F30) -> 54.775662 | T6: =AVERAGE(I23:I30) -> 0.010190786 | U6: =AVERAGE(L23:L30) -> 6.2528118
D7: X5 | E7: 73.461063 | F7: 120.42797 | R7: 5 | S7: =AVERAGE(F31:F35) -> 44.454998 | T7: =AVERAGE(I31:I35) -> 0.010996459 | U7: =AVERAGE(L31:L35) -> 1.1109139
D8: X6 | E8: 67.972813 | F8: 128.25059 | R8: 6 | S8: =AVERAGE(F36:F40) -> 35.910772 | T8: =AVERAGE(I36:I40) -> 0.030820924 | U8: =AVERAGE(L36:L40) -> 0.94054811
B9: 2 | C9: AI16 | D9: X1 | E9: 61.440536 | F9: 107.79041 | G9: 0.00080662139 | H9: 1.3128489e-05 | I9: 0.0014151252 | J9: 4.3258401 | K9: 0.070406941 | L9: 7.5891932 | R9: 7 | S9: =AVERAGE(F41:F42) -> 39.838378 | T9: =AVERAGE(I41:I42) -> 0.00032412027 | U9: =AVERAGE(L41:L42) -> 1.6803524
D10: X2 | E10: 42.379986 | F10: 79.962237 | G10: 0.00055581013 | H10: 1.311492e-05 | I10: 0.0010486984 | J10: 2.3402086 | K10: 0.055219665 | L10: 4.4154879 | R10: 8
D11: X3 | E11: 43.410286 | F11: 79.6519 | G11: 0.00051710469 | H11: 1.1912032e-05 | I11: 0.00094881595 | J11: 2.5787423 | K11: 0.059403946 | L11: 4.7316372 | R11: 9 | S11: =AVERAGE(F43:F47) -> 25.739559 | T11: =AVERAGE(I43:I47) -> 0.013242268 | U11: =AVERAGE(L43:L47) -> 0.76697173
D12: X4 | E12: 43.925436 | F12: 78.438278 | G12: 0.00044124203 | H12: 1.0045251e-05 | I12: 0.00078793219 | J12: 3.1009376 | K12: 0.070595488 | L12: 5.5373885 | R12: 10 | S12: =AVERAGE(F48:F57) -> 50.060703 | T12: =AVERAGE(I48:I57) -> 0.0087163256 | U12: =AVERAGE(L48:L57) -> 6.4126147
D13: X5 | E13: 78.955636 | F13: 147.58063 | G13: 0.0011487775 | H13: 1.4549658e-05 | I13: 0.0021472476 | J13: 5.2026125 | K13: 0.065892858 | L13: 9.7245094 | R13: 11 | S13: =AVERAGE(F58:F70) -> 6.1273492 | T13: =AVERAGE(I58:I70) -> 0.0041933841 | U13: =AVERAGE(L58:L70) -> 0.67042739
D14: X6 | E14: 44.440586 | F14: 77.287975 | G14: 0.00052174934 | H14: 1.174038e-05 | I14: 0.00090739016 | J14: 3.3201307 | K14: 0.074709426 | L14: 5.7741403
B15: 3 | C15: AI22 | D15: PX1 | E15: 41.43907 | F15: 72.700123 | G15: 0.00018735551 | H15: 4.5212287e-06 | I15: 0.00032869388 | J15: 0.12561335 | K15: 0.0030312782 | L15: 0.2203743
D16: PX2 | E16: 30.71279 | F16: 46.889756 | G16: 4.014761e-05 | H16: 1.3071951e-06 | I16: 6.129406e-05 | J16: 0.11514557 | K16: 0.0037491081 | L16: 0.17579476
D17: PX3 | E17: 24.65011 | F17: 44.018054 | G17: 9.3677756e-05 | H17: 3.8002977e-06 | I17: 0.00016728171 | J17: 0.094210011 | K17: 0.0038218901 | L17: 0.16823216
C18: AI23 | D18: TX1 | E18: 42.37179 | F18: 79.946774
D19: TX2 | E19: 46.10267 | F19: 83.823036
D20: TX3 | E20: 49.36719 | F20: 99.731697
D21: TX4 | E21: 40.97271 | F21: 72.518071
D22: TX5 | E22: 42.37179 | F22: 78.466278
B23: 4 | C23: AI30 | D23: X1 | E23: 52.829016 | F23: 91.084511
D24: X2 | E24: 67.752536 | F24: 107.54371
C25: AI30 | D25: PX1 | E25: 19.058941 | F25: 32.30329 | G25: 0.0038134984 | H25: 0.00020008973 | I25: 0.0064635566 | J25: 4.8196797 | K25: 0.25288287 | L25: 8.1689487
D26: PX2 | E26: 30.086821 | F26: 62.680877 | G26: 0.011610931 | H26: 0.00038591418 | I26: 0.024189439
D27: PX3 | E27: 15.382981 | F27: 29.582656 | G27: 0.0028974066 | H27: 0.00018835144 | I27: 0.0055719357 | J27: 3.6284662 | K27: 0.23587536 | L27: 6.9778197
D28: PX4 | E28: 27.023521 | F28: 45.417683 | G28: 0.0061995979 | H28: 0.00022941488 | I28: 0.010419492 | J28: 4.321264 | K28: 0.15990751 | L28: 7.2626286
D29: PX5 | E29: 23.347561 | F29: 42.839562 | G29: 0.0059439444 | H29: 0.00025458524 | I29: 0.01090632 | J29: 4.6651709 | K29: 0.19981405 | L29: 8.5599465
C30: AI30 | D30: PX1 | E30: 15.382981 | F30: 26.753011 | G30: 0.0020665326 | H30: 0.00013433889 | I30: 0.0035939698 | J30: 0.16946133 | K30: 0.011016157 | L30: 0.29471536
B31: 5 | C31: DC3 | D31: X1 | E31: 29.915383 | F31: 60.435117 | G31: 0.0045611539 | H31: 0.00015246851 | I31: 0.0092144523 | J31: 0.61770576 | K31: 0.020648432 | L31: 1.2478904
D32: X2 | E32: 28.916998 | F32: 55.079996 | G32: 0.0043822851 | H32: 0.00015154703 | I32: 0.0083472097 | J32: 0.50944805 | K32: 0.017617598 | L32: 0.97037724
D33: X3 | E33: 24.257868 | F33: 51.612485 | G33: 0.0072292799 | H33: 0.00029801794 | I33: 0.015381446 | J33: 0.66865057 | K33: 0.027564276 | L33: 1.4226608
D34: X4 | E34: 10.280478 | F34: 18.14202 | G34: 0.0076019231 | H34: 0.00073945231 | I34: 0.013415158 | J34: 0.71322727 | K34: 0.069376859 | L34: 1.2586364
D35: X5 | E35: 17.269173 | F35: 37.005371 | G35: 0.0040245475 | H35: 0.00023304808 | I35: 0.0086240305 | J35: 0.30566883 | K35: 0.017700259 | L35: 0.65500464
B36: 6 | C36: DC7 | D36: X1 | E36: 20.227964 | F36: 36.446783 | G36: 0.0087793229 | H36: 0.0004340191 | I36: 0.0158186 | J36: 0.35914806 | K36: 0.017755027 | L36: 0.64711362
D37: X2 | E37: 12.877324 | F37: 25.004513 | G37: 0.0007203547 | H37: 5.593978e-05 | I37: 0.001398747 | J37: 0.018576624 | K37: 0.0014425841 | L37: 0.036071114
D38: X3 | E38: 22.065624 | F38: 45.970051 | G38: 0.014542161 | H38: 0.00065904142 | I38: 0.030296168 | J38: 0.57587534 | K38: 0.026098302 | L38: 1.1997403
D39: X4 | E39: 22.065624 | F39: 40.487384 | G39: 0.046958122 | H39: 0.0021281121 | I39: 0.086161692 | J39: 1.0650598 | K39: 0.048267828 | L39: 1.9542381
D40: X5 | E40: 14.714984 | F40: 31.645128 | G40: 0.0094996776 | H40: 0.0006455785 | I40: 0.020429414 | J40: 0.40249351 | K40: 0.027352629 | L40: 0.86557745
...

Sheet Sheet3
B1: Biochem Date | C1: Experiment | D1: Sample | E1: Picogreen | G1: Proline Incorporation | J1: S35 Incorporation
E2: Raw | F2: Picogreen (DW) | G2: Raw | H2: DNA | I2: DW | J2: Raw | K2: DNA | L2: DW
B3: 1 | C3: AI9 | D3: X1 | E3: 31.750363 | F3: 56.195333 | Q3: Pico | R3: Proline | S3: S35
D4: X2 | E4: 42.726863 | F4: 101.73063 | P4: 1 | Q4: =AVERAGE(F3:F7) -> 61.419817
D5: X3 | E5: 20.773863 | F5: 47.756008 | P5: 2 | Q5: =AVERAGE(F8:F10) -> 75.55918 | R5: =AVERAGE(I8:I10) -> 0.0048104708 | S5: =AVERAGE(L8:L10) -> 2.3003255
D6: X4 | E6: 25.164463 | F6: 49.342085 | P6: 3 | Q6: =AVERAGE(F11:F27) -> 51.191006 | R6: =AVERAGE(I11:I27) -> 0.0040325917 | S6: =AVERAGE(L11:L27) -> 1.2506067
D7: X5 | E7: 21.871513 | F7: 52.075032 | P7: 4 | Q7: =AVERAGE(F28:F35) -> 21.369337 | R7: =AVERAGE(I28:I35) -> 0.0049596739 | S7: =AVERAGE(L28:L35) -> 3.8817988
B8: 2 | C8: AI19 | D8: X1 | E8: 29.501236 | F8: 80.457916 | G8: 0.0030613574 | H8: 0.00010377048 | I8: 0.0083491567 | J8: 1.5932451 | K8: 0.054006047 | L8: 4.345214 | P8: 5 | Q8: =AVERAGE(F36:F45) -> 27.663029 | R8: =AVERAGE(I36:I45) -> 0.0069601431 | S8: =AVERAGE(L36:L45) -> 1.0143313
D9: X3 | E9: 24.864886 | F9: 52.347128 | G9: 0.00060049704 | H9: 2.4150404e-05 | I9: 0.0012642043 | J9: 0.10971448 | K9: 0.0044124266 | L9: 0.23097786 | P9: 6 | Q9: =AVERAGE(F46:F49) -> 29.661331 | R9: =AVERAGE(I46:I49) -> 0.0067249063 | S9: =AVERAGE(L46:L49) -> 7.5659127
D10: X4 | E10: 40.834536 | F10: 93.872496 | G10: 0.0020958524 | H10: 5.1325486e-05 | I10: 0.0048180515 | J10: 1.0112813 | K10: 0.024765344 | L10: 2.3247847
B11: 3 | C11: AI22 | D11: PX1 | E11: 41.43907 | F11: 72.700123 | G11: 0.00018735551 | H11: 4.5212287e-06 | I11: 0.00032869388 | J11: 0.12561335 | K11: 0.0030312782 | L11: 0.2203743
D12: PX2 | E12: 30.71279 | F12: 46.889756 | G12: 4.014761e-05 | H12: 1.3071951e-06 | I12: 6.129406e-05 | J12: 0.11514557 | K12: 0.0037491081 | L12: 0.17579476
D13: PX3 | E13: 24.65011 | F13: 44.018054 | G13: 9.3677756e-05 | H13: 3.8002977e-06 | I13: 0.00016728171 | J13: 0.094210011 | K13: 0.0038218901 | L13: 0.16823216
D14: PX4 | E14: 31.17915 | F14: 52.846017 | G14: 0 | H14: 0 | I14: 0 | J14: 0.12037946 | K14: 0.0038608961 | L14: 0.20403298
D15: PX5 | E15: 34.91003 | F15: 53.297756 | G15: 0.00020073805 | H15: 5.750154e-06 | I15: 0.0003064703 | J15: 0.088976122 | K15: 0.0025487266 | L15: 0.13584141
D16: TX1 | E16: 30.24643 | F16: 63.013396
D17: TX2 | E17: 23.71739 | F17: 41.247635
D18: TX3 | E18: 27.44827 | F18: 57.183896
D19: TX4 | E19: 43.77087 | F19: 84.17475
D20: TX5 | E20: 22.31831 | F20: 35.997274
C21: AI24 | D21: PX1 | E21: 18.12107 | F21: 34.407095 | G21: 0.0070060981 | H21: 0.00038662718 | I21: 0.013302718 | J21: 2.1140803 | K21: 0.11666421 | L21: 4.0140765
D22: PX2 | E22: 23.25103 | F22: 49.470277 | G22: 0.0066089913 | H22: 0.0002842451 | I22: 0.014061684 | J22: 1.8028705 | K22: 0.077539382 | L22: 3.8358947
D23: TX1 | E23: 26.98191 | F23: 52.905706
D24: TX2 | E24: 34.44367 | F24: 56.005967
D25: TX3 | E25: 32.11187 | F25: 48.654348
D26: TX4 | E26: 26.51555 | F26: 40.793154
D27: TX5 | E27: 19.05379 | F27: 36.641904
B28: 4 | C28: AI30 | D28: PX1 | E28: 13.545001 | F28: 25.317759 | G28: 0.003195669 | H28: 0.00023592977 | I28: 0.0059732131 | J28: 3.8926265 | K28: 0.28738473 | L28: 7.2759375
D29: PX2 | E29: 15.076651 | F29: 25.994226 | G29: 0.0031104512 | H29: 0.00020630916 | I29: 0.0053628469 | J29: 3.2446861 | K29: 0.21521266 | L29: 5.5942865
D30: PX3 | E30: 15.382981 | F30: 25.012977 | G30: 0.0027269709 | H30: 0.00017727194 | I30: 0.004434099 | J30: 2.9057635 | K30: 0.18889469 | L30: 4.7248187
D31: PX4 | E31: 12.319681 | F31: 19.870453 | G31: 0.0019813148 | H31: 0.00016082517 | I31: 0.003195669 | J31: 3.0901773 | K31: 0.25083257 | L31: 4.9841569
D32: PX5 | E32: 13.851331 | F32: 23.34494 | G32: 0.0035578448 | H32: 0.00025685942 | I32: 0.0059963677 | J32: 4.3810739 | K32: 0.31629263 | L32: 7.3838324
C33: AI30 | D33: PX1 | E33: 13.851331 | F33: 25.890339 | G33: 0.0030039289 | H33: 0.00021686933 | I33: 0.0056148203 | J33: 0.20933459 | K33: 0.015112958 | L33: 0.39127961
D34: PX2 | E34: 5.8867512 | F34: 11.393712 | G34: 0.0029826244 | H34: 0.00050666732 | I34: 0.0057728215 | J34: 0.22927122 | K34: 0.038946986 | L34: 0.44375074
D35: PX3 | E35: 7.4184012 | F35: 14.130288 | G35: 0.0017469657 | H35: 0.00023549087 | I35: 0.0033275538 | J35: 0.13457224 | K35: 0.018140329 | L35: 0.25632807
B36: 5 | C36: DC2 | D36: X2 | E36: 12.277248 | F36: 24.073035 | G36: 0.0010543324 | H36: 8.587693e-05 | I36: 0.0020673184 | J36: 0.6929059 | K36: 0.05643821 | L36: 1.358639
C37: DC4 | D37: X1 | E37: 17.269173 | F37: 31.398496 | G37: 0.0066016566 | H37: 0.00038227984 | I37: 0.012003012 | J37: 0.4364028 | K37: 0.025270626 | L37: 0.79345964
D38: X2 | E38: 17.934763 | F38: 42.701817 | G38: 0.0026296292 | H38: 0.00014662191 | I38: 0.006261022 | J38: 0.22968569 | K38: 0.012806731 | L38: 0.54687068
D39: X3 | E39: 13.275633 | F39: 33.189082 | G39: 0.0049098672 | H39: 0.00036984053 | I39: 0.012274668 | J39: 0.3273021 | K39: 0.02465435 | L39: 0.81825526
D40: X4 | E40: 5.621348 | F40: 14.600904 | G40: 0.0050937573 | H40: 0.00090614518 | I40: 0.013230539 | J40: 0.41917638 | K40: 0.074568659 | L40: 1.0887698
...

Sheet Alamar Blue (Raw)
A1: Table of Contents | B1: 4m Male | Q1: 24m Male
B2: DC3 - D7 5% | D2: 1 | E2: 2 | F2: 3 | G2: 4 | H2: 5 | I2: 6 | J2: 7 | K2: 8 | L2: 9 | M2: 10 | N2: 11 | O2: 12 | Q2: DC2 -D7 5% | S2: 1 | T2: 2 | U2: 3 | V2: 4 | W2: 5 | X2: 6 | Y2: 7 | Z2: 8 | AA2: 9 | AB2: 10 | AC2: 11 | AD2: 12
C3: A | D3: 69 | E3: 63 | F3: 67 | G3: 0 | H3: 2 | I3: 2 | J3: 0 | K3: 3 | L3: 4 | M3: 3 | N3: 1 | O3: 0 | R3: A | S3: 67 | T3: 64 | U3: 61 | V3: 2 | W3: 5 | X3: 2 | Y3: 4 | Z3: 2 | AA3: 2 | AB3: 2 | AC3: 2 | AD3: 3
C4: B | D4: 105 | E4: 106 | F4: 102 | G4: 3 | H4: 4 | I4: 2 | J4: 1 | K4: 0 | L4: 5 | M4: 0 | N4: 0 | O4: 4 | R4: B | S4: 196 | T4: 196 | U4: 193 | V4: 2 | W4: 1 | X4: 6 | Y4: 2 | Z4: 0 | AA4: 0 | AB4: 5 | AC4: 2 | AD4: 1
C5: C | D5: 91 | E5: 85 | F5: 82 | G5: 3 | H5: 5 | I5: 2 | J5: 4 | K5: 4 | L5: 0 | M5: 1 | N5: 2 | O5: 4 | R5: C | S5: 373 | T5: 374 | U5: 375 | V5: 2 | W5: 2 | X5: 2 | Y5: 2 | Z5: 1 | AA5: 0 | AB5: 3 | AC5: 2 | AD5: 3
C6: D | D6: 93 | E6: 91 | F6: 88 | G6: 0 | H6: 5 | I6: 4 | J6: 5 | K6: 0 | L6: 3 | M6: 1 | N6: 2 | O6: 1 | R6: D | S6: 136 | T6: 140 | U6: 139 | V6: 3 | W6: 0 | X6: 2 | Y6: 2 | Z6: 1 | AA6: 2 | AB6: 7 | AC6: 3 | AD6: 1
C7: E | D7: 93 | E7: 89 | F7: 92 | G7: 2 | H7: 2 | I7: 3 | J7: 1 | K7: 2 | L7: 5 | M7: 1 | N7: 1 | O7: 3 | R7: E | S7: 3 | T7: 1 | U7: 7 | V7: 2 | W7: 3 | X7: 2 | Y7: 0 | Z7: 2 | AA7: 3 | AB7: 1 | AC7: 2 | AD7: 3
C8: F | D8: 95 | E8: 93 | F8: 97 | G8: 0 | H8: 2 | I8: 0 | J8: 1 | K8: 3 | L8: 0 | M8: 4 | N8: 0 | O8: 1 | R8: F | S8: 3 | T8: 3 | U8: 6 | V8: 5 | W8: 0 | X8: 0 | Y8: 1 | Z8: 6 | AA8: 0 | AB8: 4 | AC8: 0 | AD8: 4
C9: G | D9: 0 | E9: 6 | F9: 2 | G9: 1 | H9: 3 | I9: 5 | J9: 2 | K9: 0 | L9: 0 | M9: 5 | N9: 1 | O9: 3 | R9: G | S9: 3 | T9: 3 | U9: 2 | V9: 4 | W9: 3 | X9: 6 | Y9: 4 | Z9: 4 | AA9: 2 | AB9: 4 | AC9: 2 | AD9: 2
C10: H | D10: 0 | E10: 6 | F10: 3 | G10: 2 | H10: 0 | I10: 0 | J10: 2 | K10: 1 | L10: 0 | M10: 2 | N10: 3 | O10: 1 | R10: H | S10: 2 | T10: 4 | U10: 3 | V10: 0 | W10: 4 | X10: 6 | Y10: 1 | Z10: 1 | AA10: 4 | AB10: 2 | AC10: 0 | AD10: 3
B11: DC7 - D7 15% | D11: 1 | E11: 2 | F11: 3 | G11: 4 | H11: 5 | I11: 6 | J11: 7 | K11: 8 | L11: 9 | M11: 10 | N11: 11 | O11: 12 | Q11: DC4 -D7 5% | S11: 1 | T11: 2 | U11: 3 | V11: 4 | W11: 5 | X11: 6 | Y11: 7 | Z11: 8 | AA11: 9 | AB11: 10 | AC11: 11 | AD11: 12
C12: A | D12: 56 | E12: 59 | F12: 55 | G12: 3 | H12: 1 | I12: 1 | J12: 0 | K12: 0 | L12: 2 | M12: 2 | N12: 0 | O12: 6 | R12: A | S12: 70 | T12: 70 | U12: 70 | V12: 2 | W12: 0 | X12: 1 | Y12: 4 | Z12: 2 | AA12: 4 | AB12: 2 | AC12: 7 | AD12: 6
C13: B | D13: 210 | E13: 215 | F13: 203 | G13: 2 | H13: 2 | I13: 6 | J13: 1 | K13: 2 | L13: 2 | M13: 0 | N13: 0 | O13: 4 | R13: B | S13: 198 | T13: 191 | U13: 198 | V13: 2 | W13: 4 | X13: 8 | Y13: 0 | Z13: 3 | AA13: 5 | AB13: 0 | AC13: 3 | AD13: 4
C14: C | D14: 207 | E14: 214 | F14: 205 | G14: 2 | H14: 2 | I14: 0 | J14: 2 | K14: 5 | L14: 0 | M14: 4 | N14: 2 | O14: 3 | R14: C | S14: 177 | T14: 181 | U14: 184 | V14: 4 | W14: 0 | X14: 3 | Y14: 3 | Z14: 1 | AA14: 3 | AB14: 6 | AC14: 4 | AD14: 2
C15: D | D15: 136 | E15: 136 | F15: 133 | G15: 5 | H15: 7 | I15: 0 | J15: 2 | K15: 0 | L15: 1 | M15: 0 | N15: 5 | O15: 0 | R15: D | S15: 189 | T15: 193 | U15: 186 | V15: 1 | W15: 7 | X15: 0 | Y15: 6 | Z15: 3 | AA15: 3 | AB15: 3 | AC15: 0 | AD15: 3
C16: E | D16: 177 | E16: 185 | F16: 183 | G16: 3 | H16: 2 | I16: 2 | J16: 2 | K16: 1 | L16: 4 | M16: 1 | N16: 3 | O16: 0 | R16: E | S16: 192 | T16: 197 | U16: 195 | V16: 3 | W16: 0 | X16: 5 | Y16: 3 | Z16: 4 | AA16: 2 | AB16: 3 | AC16: 2 | AD16: 3
C17: F | D17: 184 | E17: 191 | F17: 191 | G17: 0 | H17: 1 | I17: 2 | J17: 5 | K17: 3 | L17: 5 | M17: 0 | N17: 0 | O17: 1 | R17: F | S17: 192 | T17: 190 | U17: 201 | V17: 2 | W17: 1 | X17: 4 | Y17: 4 | Z17: 4 | AA17: 0 | AB17: 7 | AC17: 3 | AD17: 5
C18: G | D18: 0 | E18: 4 | F18: 2 | G18: 1 | H18: 2 | I18: 4 | J18: 0 | K18: 2 | L18: 2 | M18: 0 | N18: 2 | O18: 3 | R18: G | S18: 6 | T18: 2 | U18: 0 | V18: 0 | W18: 2 | X18: 4 | Y18: 5 | Z18: 1 | AA18: 4 | AB18: 6 | AC18: 6 | AD18: 6
C19: H | D19: 0 | E19: 3 | F19: 2 | G19: 3 | H19: 0 | I19: 0 | J19: 2 | K19: 1 | L19: 5 | M19: 0 | N19: 3 | O19: 3 | R19: H | S19: 1 | T19: 0 | U19: 1 | V19: 3 | W19: 3 | X19: 2 | Y19: 0 | Z19: 3 | AA19: 0 | AB19: 8 | AC19: 1 | AD19: 3
B20: DC8 - D1 15% | D20: 1 | E20: 2 | F20: 3 | G20: 4 | H20: 5 | I20: 6 | J20: 7 | K20: 8 | L20: 9 | M20: 10 | N20: 11 | O20: 12 | Q20: DC5 - D7 15% | S20: 1 | T20: 2 | U20: 3 | V20: 4 | W20: 5 | X20: 6 | Y20: 7 | Z20: 8 | AA20: 9 | AB20: 10 | AC20: 11 | AD20: 12
C21: A | D21: 54 | E21: 57 | F21: 52 | G21: 1 | H21: 1 | I21: 1 | J21: 2 | K21: 5 | L21: 1 | M21: 5 | N21: 0 | O21: 2 | R21: A | S21: 66 | T21: 61 | U21: 63 | V21: 0 | W21: 0 | X21: 1 | Y21: 2 | Z21: 3 | AA21: 3 | AB21: 3 | AC21: 6 | AD21: 0
C22: B | D22: 81 | E22: 80 | F22: 74 | G22: 3 | H22: 1 | I22: 5 | J22: 4 | K22: 4 | L22: 2 | M22: 3 | N22: 0 | O22: 0 | R22: B | S22: 195 | T22: 194 | U22: 199 | V22: 6 | W22: 3 | X22: 3 | Y22: 1 | Z22: 5 | AA22: 3 | AB22: 4 | AC22: 4 | AD22: 1
C23: C | D23: 69 | E23: 68 | F23: 74 | G23: 4 | H23: 0 | I23: 2 | J23: 1 | K23: 4 | L23: 2 | M23: 2 | N23: 0 | O23: 4 | R23: C | S23: 147 | T23: 142 | U23: 147 | V23: 2 | W23: 3 | X23: 2 | Y23: 1 | Z23: 0 | AA23: 2 | AB23: 2 | AC23: 1 | AD23: 5
C24: D | D24: 72 | E24: 74 | F24: 74 | G24: 7 | H24: 4 | I24: 2 | J24: 4 | K24: 2 | L24: 5 | M24: 3 | N24: 2 | O24: 3 | R24: D | S24: 51 | T24: 55 | U24: 61 | V24: 2 | W24: 3 | X24: 0 | Y24: 0 | Z24: 0 | AA24: 4 | AB24: 5 | AC24: 0 | AD24: 2
C25: E | D25: 96 | E25: 93 | F25: 96 | G25: 4 | H25: 3 | I25: 3 | J25: 5 | K25: 2 | L25: 3 | M25: 2 | N25: 3 | O25: 3 | R25: E | S25: 49 | T25: 52 | U25: 51 | V25: 1 | W25: 5 | X25: 2 | Y25: 4 | Z25: 3 | AA25: 1 | AB25: 2 | AC25: 1 | AD25: 7
C26: F | D26: 76 | E26: 72 | F26: 72 | G26: 0 | H26: 5 | I26: 6 | J26: 2 | K26: 0 | L26: 4 | M26: 7 | N26: 1 | O26: 3 | R26: F | S26: 214 | T26: 219 | U26: 218 | V26: 3 | W26: 2 | X26: 2 | Y26: 5 | Z26: 2 | AA26: 5 | AB26: 7 | AC26: 4 | AD26: 1
C27: G | D27: 85 | E27: 90 | F27: 85 | G27: 3 | H27: 7 | I27: 3 | J27: 4 | K27: 6 | L27: 3 | M27: 1 | N27: 3 | O27: 4 | R27: G | S27: 159 | T27: 156 | U27: 148 | V27: 5 | W27: 3 | X27: 5 | Y27: 4 | Z27: 3 | AA27: 5 | AB27: 3 | AC27: 3 | AD27: 3
